IntegrityError at /register/learner/
UNIQUE constraint failed: users_learnerprofile.user_id
Request Method:	POST
Request URL:	http://c04fd6df-be0d-492d-b2f8-d8a5ecbe079b-00-mp4il0lqopkm.riker.replit.dev/register/learner/
Django Version:	5.2
Exception Type:	IntegrityError
Exception Value:	
UNIQUE constraint failed: users_learnerprofile.user_id
Exception Location:	/home/runner/workspace/.pythonlibs/lib/python3.11/site-packages/django/db/backends/sqlite3/base.py, line 360, in execute
Raised during:	users.views.register_view
Python Executable:	/home/runner/workspace/.pythonlibs/bin/python
Python Version:	3.11.10
Python Path:	
['/home/runner/workspace',
 '/nix/store/lc7qv2ldzrs1aq3hbyzmbgvn0h2w26pl-sitecustomize/lib/python/site-packages',
 '/nix/store/dfg63lldbvcj207iyr9z0xw21d8ax02n-python3.11-pip-24.0/lib/python3.11/site-packages',
 '/nix/store/clx0mcir7qw8zk36zbr4jra789g3knf6-python3-3.11.10/lib/python311.zip',
 '/nix/store/clx0mcir7qw8zk36zbr4jra789g3knf6-python3-3.11.10/lib/python3.11',
 '/nix/store/clx0mcir7qw8zk36zbr4jra789g3knf6-python3-3.11.10/lib/python3.11/lib-dynload',
 '/home/runner/workspace/.pythonlibs/lib/python3.11/site-packages',
 '/home/runner/workspace/.pythonlibs/lib/python3.11/site-packages',
 '/nix/store/wblvmd5y7izx0z10d1w7ga7zc4apjxmb-python3.11-setuptools-75.1.1/lib/python3.11/site-packages',
 '/home/runner/workspace/.pythonlibs/lib/python3.11/site-packages/setuptools/_vendor']
Server time:	Mon, 28 Apr 2025 04:10:42 +0000
Traceback Switch to copy-and-paste view
/home/runner/workspace/.pythonlibs/lib/python3.11/site-packages/django/db/backends/utils.py, line 105, in _execute
                return self.cursor.execute(sql, params)
                            ^^^^^^^^^^^^^^^^^^^^^^^^^^^^^^^^ …
Local vars
/home/runner/workspace/.pythonlibs/lib/python3.11/site-packages/django/db/backends/sqlite3/base.py, line 360, in execute
        return super().execute(query, params)
                    ^^^^^^^^^^^^^^^^^^^^^^^^^^^^^^ …
Local vars
The above exception (UNIQUE constraint failed: users_learnerprofile.user_id) was the direct cause of the following exception:
/home/runner/workspace/.pythonlibs/lib/python3.11/site-packages/django/core/handlers/exception.py, line 42, in inner
                response = await get_response(request)
                               ^^^^^^^^^^^^^^^^^^^^^^^^^^^ …
Local vars
/home/runner/workspace/.pythonlibs/lib/python3.11/site-packages/django/core/handlers/base.py, line 253, in _get_response_async
                response = await wrapped_callback(
                                 …
Local vars
/home/runner/workspace/.pythonlibs/lib/python3.11/site-packages/django/utils/decorators.py, line 192, in _view_wrapper
                        result = _process_exception(request, e)
                                      ^^^^^^^^^^^^^^^^^^^^^^^^^^^^^^ …
Local vars
/home/runner/workspace/.pythonlibs/lib/python3.11/site-packages/django/utils/decorators.py, line 190, in _view_wrapper
                        response = view_func(request, *args, **kwargs)
                                        ^^^^^^^^^^^^^^^^^^^^^^^^^^^^^^^^^^^ …
Local vars
/home/runner/workspace/users/views.py, line 114, in register_view
            profile.save()
                 ^^^^^^^^^^^^^^ …
Local vars
/home/runner/workspace/.pythonlibs/lib/python3.11/site-packages/django/db/models/base.py, line 902, in save
        self.save_base(
             ^ …
Local vars
/home/runner/workspace/.pythonlibs/lib/python3.11/site-packages/django/db/models/base.py, line 1008, in save_base
            updated = self._save_table(
                             …
Local vars
/home/runner/workspace/.pythonlibs/lib/python3.11/site-packages/django/db/models/base.py, line 1169, in _save_table
            results = self._do_insert(
                             …
Local vars
/home/runner/workspace/.pythonlibs/lib/python3.11/site-packages/django/db/models/base.py, line 1210, in _do_insert
        return manager._insert(
                      …
Local vars
/home/runner/workspace/.pythonlibs/lib/python3.11/site-packages/django/db/models/manager.py, line 87, in manager_method
                return getattr(self.get_queryset(), name)(*args, **kwargs)
                           ^^^^^^^^^^^^^^^^^^^^^^^^^^^^^^^^^^^^^^^^^^^^^^^^^^^ …
Local vars
/home/runner/workspace/.pythonlibs/lib/python3.11/site-packages/django/db/models/query.py, line 1854, in _insert
        return query.get_compiler(using=using).execute_sql(returning_fields)
                     ^^^^^^^^^^^^^^^^^^^^^^^^^^^^^^^^^^^^^^^^^^^^^^^^^^^^^^^^^^^^^ …
Local vars
/home/runner/workspace/.pythonlibs/lib/python3.11/site-packages/django/db/models/sql/compiler.py, line 1881, in execute_sql
                cursor.execute(sql, params)
                      ^^^^^^^^^^^^^^^^^^^^^^^^^^^ 